<?xml version="1.0" ?>
<!-- =================================================================================== -->
<!-- |    This document was autogenerated by xacro from demo05_car_base.urdf.xacro     | -->
<!-- |    EDITING THIS FILE BY HAND IS NOT RECOMMENDED                                 | -->
<!-- =================================================================================== -->
<robot name="mycar">
  <!-- 1、添加 base_footprint -->
  <link name="base_footprint">
    <visual>
      <geometry>
        <sphere radius="0.001"/>
      </geometry>
    </visual>
  </link>
  <!-- 2.1.link 底盘只有一个，无需复用 -->
  <link name="base_link">
    <visual>
      <geometry>
        <cylinder length="0.08" radius="0.1"/>
      </geometry>
      <origin rpy="0 0 0 " xyz="0 0 0"/>
      <material name="baselink_color">
        <color rgba="1.0 0.5 0.2 0.5"/>
      </material>
    </visual>
  </link>
  <!-- 2.2.joint -->
  <joint name="link2footprint" type="fixed">
    <parent link="base_footprint"/>
    <child link="base_link"/>
    <!-- 关节 z 上的设置 = 车体高度/2 + 离地距离 -->
    <origin rpy="0.0 0.0 0.0" xyz="0 0 0.055"/>
  </joint>
  <!-- 3、添加驱动轮 -->
  <!-- 
        形状：圆柱
        半径：0.0325m
        长度：0.015m
     -->
  <!-- 3.1、link -->
  <link name="left_wheel">
    <visual>
      <geometry>
        <cylinder length="0.015" radius="0.0325"/>
      </geometry>
      <origin rpy="1.57079635 0 0" xyz="0 0 0"/>
      <material name="wheel_color">
        <color rgba="0 0 0 0.8"/>
      </material>
    </visual>
  </link>
  <!-- 3.2、joint -->
  <joint name="left2link" type="continuous">
    <parent link="base_link"/>
    <child link="left_wheel"/>
    <!-- 
                x 无偏移
                y 车体半径
                z 等于车体高度 / 2 + 离地间距 - 车轮半径
            -->
    <origin rpy="0.0 0.0 0.0" xyz="0.0 0.1 -0.0225"/>
    <axis xyz="0.0 1.0 0.0"/>
  </joint>
  <!-- 3.1、link -->
  <link name="right_wheel">
    <visual>
      <geometry>
        <cylinder length="0.015" radius="0.0325"/>
      </geometry>
      <origin rpy="1.57079635 0 0" xyz="0 0 0"/>
      <material name="wheel_color">
        <color rgba="0 0 0 0.8"/>
      </material>
    </visual>
  </link>
  <!-- 3.2、joint -->
  <joint name="right2link" type="continuous">
    <parent link="base_link"/>
    <child link="right_wheel"/>
    <!-- 
                x 无偏移
                y 车体半径
                z 等于车体高度 / 2 + 离地间距 - 车轮半径
            -->
    <origin rpy="0.0 0.0 0.0" xyz="0.0 -0.1 -0.0225"/>
    <axis xyz="0.0 1.0 0.0"/>
  </joint>
  <!-- 4、添加万象轮 -->
  <!-- 
        形状：球
        半径：0.0075m
     -->
  <!-- 4.1、link -->
  <link name="front_wheel">
    <visual>
      <geometry>
        <sphere radius="0.0075"/>
      </geometry>
      <origin rpy="0 0 0" xyz="0 0 0"/>
      <material name="wheel_color">
        <color rgba="0 0 0 0.8"/>
      </material>
    </visual>
  </link>
  <!-- 4.2、joint -->
  <joint name="front2link" type="continuous">
    <parent link="base_link"/>
    <child link="front_wheel"/>
    <origin rpy="0.0 0.0 0.0" xyz="0.08 0 -0.0475"/>
    <axis xyz="0 1 0"/>
  </joint>
  <!-- 4.1、link -->
  <link name="back_wheel">
    <visual>
      <geometry>
        <sphere radius="0.0075"/>
      </geometry>
      <origin rpy="0 0 0" xyz="0 0 0"/>
      <material name="wheel_color">
        <color rgba="0 0 0 0.8"/>
      </material>
    </visual>
  </link>
  <!-- 4.2、joint -->
  <joint name="back2link" type="continuous">
    <parent link="base_link"/>
    <child link="back_wheel"/>
    <origin rpy="0.0 0.0 0.0" xyz="-0.08 0 -0.0475"/>
    <axis xyz="0 1 0"/>
  </joint>
</robot>

